Channel: book.ETH-PERPETUAL.100ms, Data: {"jsonrpc":"2.0","method":"subscription","params":{"channel":"book.ETH-PERPETUAL.100ms","data":{"asks":[["new",4000.0,98.0],["new",4500.0,135.0],["new",5000.0,15450.0],["new",5007.4,2004.0],["new",5555.0,10001.0],["new",7180.4,1.0],["new",9999.95,1.0],["new",10000.0,5.0],["new",11000.0,20.0],["new",18285.0,30000.0],["new",20000.0,3400.0],["new",30100.0,170.0],["new",38500.0,40.0],["new",51853.0,10.0]],"bids":[["new",3639.25,10.0],["new",3638.45,1096.0],["new",3618.35,183.0],["new",3402.0,10.0],["new",3336.9,10.0],["new",3330.05,10.0],["new",3323.9,10.0],["new",3305.3,10.0],["new",3303.1,6091360.0],["new",3300.0,200.0],["new",3258.0,10.0],["new",3000.0,30.0],["new",2500.0,9.0],["new",2363.0,100.0],["new",2320.0,46.0],["new",2307.0,1000.0],["new",2300.0,40.0],["new",2200.0,74.0],["new",2032.0,100.0],["new",2027.05,1.0],["new",2000.0,2119.0],["new",1900.0,100.0],["new",1867.1,28.0],["new",1821.0,1.0],["new",1735.5,696.0],["new",1500.0,1403218.0],["new",1242.0,64580.0],["new",1215.1,223.0],["new",1200.0,9.0],["new",1199.9,10000.0],["new",1193.9,20000.0],["new",1102.0,43740.0],["new",1000.0,147.0],["new",942.0,131220.0],["new",900.0,4600.0],["new",800.0,17400.0],["new",762.0,393660.0],["new",750.8,386.0],["new",701.0,45.0],["new",691.0,49.0],["new",681.0,53.0],["new",671.0,56.0],["new",661.0,59.0],["new",651.0,61.0],["new",641.0,61.0],["new",631.0,62.0],["new",623.45,915.0],["new",621.0,62.0],["new",611.0,60.0],["new",601.0,58.0],["new",600.0,2506.0],["new",591.0,55.0],["new",581.0,52.0],["new",571.0,47.0],["new",561.0,43.0],["new",551.0,37.0],["new",541.0,32.0],["new",531.0,27.0],["new",524.0,87474.0],["new",521.0,22.0],["new",511.0,17.0],["new",501.0,13.0],["new",500.0,3119.0],["new",400.0,250033.0],["new",350.0,240.0],["new",332.1,301.0],["new",324.65,482.0],["new",317.2,784.0],["new",309.75,1267.0],["new",302.35,2052.0],["new",300.0,251006.0],["new",294.9,3320.0],["new",287.45,5372.0],["new",280.75,186374.0],["new",260.0,500000.0],["new",222.0,16.0],["new",212.0,2.0],["new",200.0,20.0],["new",195.0,2000.0],["new",181.0,120000.0],["new",172.05,30.0],["new",143.55,20.0],["new",140.0,100000.0],["new",135.0,200010.0],["new",130.0,300020.0],["new",125.0,400020.0],["new",120.0,30.0],["new",115.0,20.0],["new",110.0,30.0],["new",105.0,20.0],["new",100.0,524.0],["new",60.0,60.0],["new",58.0,1.0],["new",55.0,45.0],["new",50.0,760.0],["new",45.0,10000005.0],["new",40.0,80.0],["new",32.0,5.0],["new",30.0,50.0],["new",22.2,1.0],["new",21.0,10.0],["new",20.0,2140.0],["new",10.0,182.0],["new",9.95,1.0],["new",9.0,9.0],["new",6.0,200.0],["new",5.5,2.0],["new",5.0,63.0],["new",4.0,1844.0],["new",1.45,1330.0],["new",1.0,222.0],["new",0.5,1.0]],"change_id":15937773408,"instrument_name":"ETH-PERPETUAL","timestamp":1737377711147,"type":"snapshot"}}}
Channel: book.ETH-PERPETUAL.100ms, Data: {"jsonrpc":"2.0","method":"subscription","params":{"channel":"book.ETH-PERPETUAL.100ms","data":{"asks":[],"bids":[["new",3403.0,10.0],["delete",3402.0,0.0]],"change_id":15937773426,"instrument_name":"ETH-PERPETUAL","prev_change_id":15937773408,"timestamp":1737377711806,"type":"change"}}}
Channel: book.ETH-PERPETUAL.100ms, Data: {"jsonrpc":"2.0","method":"subscription","params":{"channel":"book.ETH-PERPETUAL.100ms","data":{"asks":[],"bids":[["delete",1821.0,0.0]],"change_id":15937773564,"instrument_name":"ETH-PERPETUAL","prev_change_id":15937773426,"timestamp":1737377712843,"type":"change"}}}
Channel: book.ETH-PERPETUAL.100ms, Data: {"jsonrpc":"2.0","method":"subscription","params":{"channel":"book.ETH-PERPETUAL.100ms","data":{"asks":[],"bids":[["delete",3403.0,0.0],["new",3402.0,10.0]],"change_id":15937774051,"instrument_name":"ETH-PERPETUAL","prev_change_id":15937773564,"timestamp":1737377713923,"type":"change"}}}
Channel: book.ETH-PERPETUAL.100ms, Data: {"jsonrpc":"2.0","method":"subscription","params":{"channel":"book.ETH-PERPETUAL.100ms","data":{"asks":[],"bids":[["new",3403.0,10.0],["delete",3402.0,0.0],["new",1821.0,1.0]],"change_id":15937774405,"instrument_name":"ETH-PERPETUAL","prev_change_id":15937774051,"timestamp":1737377714845,"type":"change"}}}
Channel: book.ETH-PERPETUAL.100ms, Data: {"jsonrpc":"2.0","method":"subscription","params":{"channel":"book.ETH-PERPETUAL.100ms","data":{"asks":[],"bids":[["new",3642.0,1.0],["delete",3403.0,0.0],["new",3402.0,10.0],["delete",1821.0,0.0]],"change_id":15937774794,"instrument_name":"ETH-PERPETUAL","prev_change_id":15937774405,"timestamp":1737377716850,"type":"change"}}}
Channel: book.ETH-PERPETUAL.100ms, Data: {"jsonrpc":"2.0","method":"subscription","params":{"channel":"book.ETH-PERPETUAL.100ms","data":{"asks":[],"bids":[["change",3642.0,11.0],["delete",3639.25,0.0]],"change_id":15937774962,"instrument_name":"ETH-PERPETUAL","prev_change_id":15937774794,"timestamp":1737377718172,"type":"change"}}}
Channel: book.ETH-PERPETUAL.100ms, Data: {"jsonrpc":"2.0","method":"subscription","params":{"channel":"book.ETH-PERPETUAL.100ms","data":{"asks":[],"bids":[["new",3405.0,10.0],["delete",3402.0,0.0]],"change_id":15937774964,"instrument_name":"ETH-PERPETUAL","prev_change_id":15937774962,"timestamp":1737377718180,"type":"change"}}}
Channel: book.ETH-PERPETUAL.100ms, Data: {"jsonrpc":"2.0","method":"subscription","params":{"channel":"book.ETH-PERPETUAL.100ms","data":{"asks":[],"bids":[["delete",3405.0,0.0],["new",3403.0,10.0],["new",1821.0,1.0]],"change_id":15937775037,"instrument_name":"ETH-PERPETUAL","prev_change_id":15937774964,"timestamp":1737377718887,"type":"change"}}}
Channel: book.ETH-PERPETUAL.100ms, Data: {"jsonrpc":"2.0","method":"subscription","params":{"channel":"book.ETH-PERPETUAL.100ms","data":{"asks":[],"bids":[["delete",1821.0,0.0]],"change_id":15937775263,"instrument_name":"ETH-PERPETUAL","prev_change_id":15937775037,"timestamp":1737377720872,"type":"change"}}}
Channel: book.ETH-PERPETUAL.100ms, Data: {"jsonrpc":"2.0","method":"subscription","params":{"channel":"book.ETH-PERPETUAL.100ms","data":{"asks":[],"bids":[["new",1821.0,1.0]],"change_id":15937775527,"instrument_name":"ETH-PERPETUAL","prev_change_id":15937775263,"timestamp":1737377722872,"type":"change"}}}
Channel: book.ETH-PERPETUAL.100ms, Data: {"jsonrpc":"2.0","method":"subscription","params":{"channel":"book.ETH-PERPETUAL.100ms","data":{"asks":[],"bids":[["new",3303.55,6091360.0],["delete",3303.1,0.0]],"change_id":15937775776,"instrument_name":"ETH-PERPETUAL","prev_change_id":15937775527,"timestamp":1737377724120,"type":"change"}}}
Channel: book.ETH-PERPETUAL.100ms, Data: {"jsonrpc":"2.0","method":"subscription","params":{"channel":"book.ETH-PERPETUAL.100ms","data":{"asks":[],"bids":[["change",3642.0,10.0]],"change_id":15937775854,"instrument_name":"ETH-PERPETUAL","prev_change_id":15937775776,"timestamp":1737377724538,"type":"change"}}}
Channel: book.ETH-PERPETUAL.100ms, Data: {"jsonrpc":"2.0","method":"subscription","params":{"channel":"book.ETH-PERPETUAL.100ms","data":{"asks":[],"bids":[["delete",1821.0,0.0]],"change_id":15937775855,"instrument_name":"ETH-PERPETUAL","prev_change_id":15937775854,"timestamp":1737377724885,"type":"change"}}}
Channel: book.ETH-PERPETUAL.100ms, Data: {"jsonrpc":"2.0","method":"subscription","params":{"channel":"book.ETH-PERPETUAL.100ms","data":{"asks":[],"bids":[["new",3642.15,1.0]],"change_id":15937775858,"instrument_name":"ETH-PERPETUAL","prev_change_id":15937775855,"timestamp":1737377725859,"type":"change"}}}
Channel: book.ETH-PERPETUAL.100ms, Data: {"jsonrpc":"2.0","method":"subscription","params":{"channel":"book.ETH-PERPETUAL.100ms","data":{"asks":[],"bids":[["change",3642.15,11.0],["delete",3642.0,0.0],["new",1821.0,1.0]],"change_id":15937775889,"instrument_name":"ETH-PERPETUAL","prev_change_id":15937775858,"timestamp":1737377726886,"type":"change"}}}
Channel: book.ETH-PERPETUAL.100ms, Data: {"jsonrpc":"2.0","method":"subscription","params":{"channel":"book.ETH-PERPETUAL.100ms","data":{"asks":[],"bids":[["delete",1821.0,0.0]],"change_id":15937777100,"instrument_name":"ETH-PERPETUAL","prev_change_id":15937775889,"timestamp":1737377729898,"type":"change"}}}
Channel: book.ETH-PERPETUAL.100ms, Data: {"jsonrpc":"2.0","method":"subscription","params":{"channel":"book.ETH-PERPETUAL.100ms","data":{"asks":[],"bids":[["new",3404.0,10.0],["delete",3403.0,0.0]],"change_id":15937777277,"instrument_name":"ETH-PERPETUAL","prev_change_id":15937777100,"timestamp":1737377730173,"type":"change"}}}
Channel: book.ETH-PERPETUAL.100ms, Data: {"jsonrpc":"2.0","method":"subscription","params":{"channel":"book.ETH-PERPETUAL.100ms","data":{"asks":[],"bids":[["new",3304.05,6091360.0],["delete",3303.55,0.0]],"change_id":15937777414,"instrument_name":"ETH-PERPETUAL","prev_change_id":15937777277,"timestamp":1737377730743,"type":"change"}}}
Channel: book.ETH-PERPETUAL.100ms, Data: {"jsonrpc":"2.0","method":"subscription","params":{"channel":"book.ETH-PERPETUAL.100ms","data":{"asks":[],"bids":[["new",1821.0,1.0]],"change_id":15937777501,"instrument_name":"ETH-PERPETUAL","prev_change_id":15937777414,"timestamp":1737377731899,"type":"change"}}}
Channel: book.ETH-PERPETUAL.100ms, Data: {"jsonrpc":"2.0","method":"subscription","params":{"channel":"book.ETH-PERPETUAL.100ms","data":{"asks":[],"bids":[["delete",3404.0,0.0],["new",3403.0,10.0]],"change_id":15937777623,"instrument_name":"ETH-PERPETUAL","prev_change_id":15937777501,"timestamp":1737377732999,"type":"change"}}}
Channel: book.ETH-PERPETUAL.100ms, Data: {"jsonrpc":"2.0","method":"subscription","params":{"channel":"book.ETH-PERPETUAL.100ms","data":{"asks":[],"bids":[["delete",1821.0,0.0]],"change_id":15937777760,"instrument_name":"ETH-PERPETUAL","prev_change_id":15937777623,"timestamp":1737377733905,"type":"change"}}}
Channel: book.ETH-PERPETUAL.100ms, Data: {"jsonrpc":"2.0","method":"subscription","params":{"channel":"book.ETH-PERPETUAL.100ms","data":{"asks":[],"bids":[["change",3642.15,10.0]],"change_id":15937777911,"instrument_name":"ETH-PERPETUAL","prev_change_id":15937777760,"timestamp":1737377734297,"type":"change"}}}
Channel: book.ETH-PERPETUAL.100ms, Data: {"jsonrpc":"2.0","method":"subscription","params":{"channel":"book.ETH-PERPETUAL.100ms","data":{"asks":[],"bids":[["new",1714.0,1.0]],"change_id":15962715129,"instrument_name":"ETH-PERPETUAL","prev_change_id":15962714740,"timestamp":1737453489707,"type":"change"}}}
Channel: book.BNB_USDC.100ms, Data: {"jsonrpc":"2.0","method":"subscription","params":{"channel":"book.ETH-PERPETUAL.100ms","data":{"asks":[],"bids":[["delete",3369.0,0.0],["new",3368.0,10.0]],"change_id":15962715398,"instrument_name":"ETH-PERPETUAL","prev_change_id":15962715129,"timestamp":1737453490410,"type":"change"}}}
Channel: book.ETH-PERPETUAL.100ms, Data: {"jsonrpc":"2.0","method":"subscription","params":{"channel":"book.ETH-PERPETUAL.100ms","data":{"asks":[],"bids":[["delete",1714.0,0.0]],"change_id":15962715969,"instrument_name":"ETH-PERPETUAL","prev_change_id":15962715398,"timestamp":1737453491723,"type":"change"}}}
Channel: book.BNB_USDC.100ms, Data: {"jsonrpc":"2.0","method":"subscription","params":{"channel":"book.ETH-PERPETUAL.100ms","data":{"asks":[],"bids":[["new",3604.9,50000.0]],"change_id":15962716347,"instrument_name":"ETH-PERPETUAL","prev_change_id":15962715969,"timestamp":1737453492709,"type":"change"}}}
Channel: book.ETH-PERPETUAL.100ms, Data: {"jsonrpc":"2.0","method":"subscription","params":{"channel":"book.ETH-PERPETUAL.100ms","data":{"asks":[],"bids":[["new",3605.2,50000.0],["delete",3604.9,0.0]],"change_id":15962716585,"instrument_name":"ETH-PERPETUAL","prev_change_id":15962716347,"timestamp":1737453493196,"type":"change"}}}
Channel: book.BNB_USDC.100ms, Data: {"jsonrpc":"2.0","method":"subscription","params":{"channel":"book.ETH-PERPETUAL.100ms","data":{"asks":[],"bids":[["delete",3270.7,0.0],["new",3269.2,6091360.0]],"change_id":15962716972,"instrument_name":"ETH-PERPETUAL","prev_change_id":15962716585,"timestamp":1737453494157,"type":"change"}}}
Channel: book.ETH-PERPETUAL.100ms, Data: {"jsonrpc":"2.0","method":"subscription","params":{"channel":"book.ETH-PERPETUAL.100ms","data":{"asks":[],"bids":[["new",3605.4,50000.0],["delete",3605.2,0.0]],"change_id":15962717279,"instrument_name":"ETH-PERPETUAL","prev_change_id":15962716972,"timestamp":1737453495320,"type":"change"}}}
Channel: book.BNB_USDC.100ms, Data: {"jsonrpc":"2.0","method":"subscription","params":{"channel":"book.ETH-PERPETUAL.100ms","data":{"asks":[],"bids":[["change",3605.4,50000.0]],"change_id":15962717286,"instrument_name":"ETH-PERPETUAL","prev_change_id":15962717279,"timestamp":1737453495883,"type":"change"}}}
Channel: book.ETH-PERPETUAL.100ms, Data: {"jsonrpc":"2.0","method":"subscription","params":{"channel":"book.ETH-PERPETUAL.100ms","data":{"asks":[],"bids":[["new",3369.0,10.0],["delete",3368.0,0.0]],"change_id":15962717372,"instrument_name":"ETH-PERPETUAL","prev_change_id":15962717286,"timestamp":1737453496067,"type":"change"}}}
Channel: book.BNB_USDC.100ms, Data: {"jsonrpc":"2.0","method":"subscription","params":{"channel":"book.ETH-PERPETUAL.100ms","data":{"asks":[],"bids":[["new",3605.8,50000.0],["delete",3605.4,0.0]],"change_id":15962717524,"instrument_name":"ETH-PERPETUAL","prev_change_id":15962717372,"timestamp":1737453496422,"type":"change"}}}
Channel: book.ETH-PERPETUAL.100ms, Data: {"jsonrpc":"2.0","method":"subscription","params":{"channel":"book.ETH-PERPETUAL.100ms","data":{"asks":[],"bids":[["new",3605.9,50000.0],["delete",3605.8,0.0]],"change_id":15962717736,"instrument_name":"ETH-PERPETUAL","prev_change_id":15962717524,"timestamp":1737453496946,"type":"change"}}}
Channel: book.BNB_USDC.100ms, Data: {"jsonrpc":"2.0","method":"subscription","params":{"channel":"book.ETH-PERPETUAL.100ms","data":{"asks":[],"bids":[["new",3606.35,50000.0],["delete",3605.9,0.0]],"change_id":15962718320,"instrument_name":"ETH-PERPETUAL","prev_change_id":15962717736,"timestamp":1737453498182,"type":"change"}}}
Channel: book.ETH-PERPETUAL.100ms, Data: {"jsonrpc":"2.0","method":"subscription","params":{"channel":"book.ETH-PERPETUAL.100ms","data":{"asks":[],"bids":[["new",3606.75,50000.0],["delete",3606.35,0.0],["new",3370.0,10.0],["delete",3369.0,0.0]],"change_id":15962718604,"instrument_name":"ETH-PERPETUAL","prev_change_id":15962718320,"timestamp":1737453499101,"type":"change"}}}
Channel: book.BNB_USDC.100ms, Data: {"jsonrpc":"2.0","method":"subscription","params":{"channel":"book.ETH-PERPETUAL.100ms","data":{"asks":[],"bids":[["new",3606.8,50000.0],["delete",3606.75,0.0]],"change_id":15962719093,"instrument_name":"ETH-PERPETUAL","prev_change_id":15962718604,"timestamp":1737453500212,"type":"change"}}}
Channel: book.ETH-PERPETUAL.100ms, Data: {"jsonrpc":"2.0","method":"subscription","params":{"channel":"book.ETH-PERPETUAL.100ms","data":{"asks":[],"bids":[["new",3271.25,6091360.0],["delete",3269.2,0.0]],"change_id":15962719338,"instrument_name":"ETH-PERPETUAL","prev_change_id":15962719093,"timestamp":1737453500835,"type":"change"}}}
Channel: book.BNB_USDC.100ms, Data: {"jsonrpc":"2.0","method":"subscription","params":{"channel":"book.ETH-PERPETUAL.100ms","data":{"asks":[],"bids":[["delete",3606.8,0.0],["new",3606.7,50000.0]],"change_id":15962720018,"instrument_name":"ETH-PERPETUAL","prev_change_id":15962719338,"timestamp":1737453502320,"type":"change"}}}
Channel: book.ETH-PERPETUAL.100ms, Data: {"jsonrpc":"2.0","method":"subscription","params":{"channel":"book.ETH-PERPETUAL.100ms","data":{"asks":[],"bids":[["delete",3606.7,0.0]],"change_id":15962720058,"instrument_name":"ETH-PERPETUAL","prev_change_id":15962720018,"timestamp":1737453502809,"type":"change"}}}
Channel: book.ETH-PERPETUAL.100ms, Data: {"jsonrpc":"2.0","method":"subscription","params":{"channel":"book.BNB_USDC.100ms","data":{"asks":[["new",800.0,60.0],["new",2000.0,110.0]],"bids":[["new",723.0,1.0],["new",705.85,40.0],["new",705.1,40.0],["new",705.0,1.0],["new",700.0,33.0],["new",699.0,1.0],["new",697.6,0.01],["new",691.6,0.01],["new",670.55,0.01],["new",669.65,0.01],["new",669.6,0.01],["new",669.5,0.01],["new",669.3,0.01],["new",668.95,0.01],["new",668.85,0.01],["new",668.65,0.01],["new",668.05,0.01],["new",668.0,0.01],["new",667.95,0.01],["new",634.05,1.0],["new",632.55,1.0],["new",600.0,5.5],["new",299.0,100.0],["new",199.0,100.0],["new",150.0,14.0],["new",100.0,7.02],["new",90.9,10.0],["new",77.2,10.0],["new",75.6,20.0],["new",75.0,10.0],["new",50.55,10.0],["new",12.0,203.0],["new",11.0,808.0],["new",10.0,275.0],["new",9.0,0.1],["new",8.0,0.04],["new",1.0,150.0]],"change_id":105454777,"instrument_name":"BNB_USDC","timestamp":1737453500919,"type":"snapshot"}}}
Channel: book.BNB_USDC.100ms, Data: {"jsonrpc":"2.0","method":"subscription","params":{"channel":"book.ETH-PERPETUAL.100ms","data":{"asks":[],"bids":[["new",1718.0,1.0]],"change_id":15962720126,"instrument_name":"ETH-PERPETUAL","prev_change_id":15962720058,"timestamp":1737453504717,"type":"change"}}}
Channel: book.ETH-PERPETUAL.100ms, Data: {"jsonrpc":"2.0","method":"subscription","params":{"channel":"book.ETH-PERPETUAL.100ms","data":{"asks":[],"bids":[["delete",3370.0,0.0],["new",3369.0,10.0]],"change_id":15962720263,"instrument_name":"ETH-PERPETUAL","prev_change_id":15962720126,"timestamp":1737453505340,"type":"change"}}}
Channel: book.BNB_USDC.100ms, Data: {"jsonrpc":"2.0","method":"subscription","params":{"channel":"book.ETH-PERPETUAL.100ms","data":{"asks":[],"bids":[["delete",1718.0,0.0]],"change_id":15962720419,"instrument_name":"ETH-PERPETUAL","prev_change_id":15962720263,"timestamp":1737453506733,"type":"change"}}}
Channel: book.ETH-PERPETUAL.100ms, Data: {"jsonrpc":"2.0","method":"subscription","params":{"channel":"book.ETH-PERPETUAL.100ms","data":{"asks":[],"bids":[["delete",3271.25,0.0],["new",3270.85,6091360.0]],"change_id":15962720620,"instrument_name":"ETH-PERPETUAL","prev_change_id":15962720419,"timestamp":1737453507494,"type":"change"}}}
Channel: book.BNB_USDC.100ms, Data: {"jsonrpc":"2.0","method":"subscription","params":{"channel":"book.ETH-PERPETUAL.100ms","data":{"asks":[],"bids":[["new",3606.0,50000.0]],"change_id":15962721556,"instrument_name":"ETH-PERPETUAL","prev_change_id":15962720620,"timestamp":1737453509827,"type":"change"}}}
Channel: book.ETH-PERPETUAL.100ms, Data: {"jsonrpc":"2.0","method":"subscription","params":{"channel":"book.ETH-PERPETUAL.100ms","data":{"asks":[],"bids":[["change",3606.2,50050.0],["delete",3606.0,0.0]],"change_id":15962721687,"instrument_name":"ETH-PERPETUAL","prev_change_id":15962721556,"timestamp":1737453510330,"type":"change"}}}
Channel: book.BNB_USDC.100ms, Data: {"jsonrpc":"2.0","method":"subscription","params":{"channel":"book.ETH-PERPETUAL.100ms","data":{"asks":[],"bids":[["new",3606.45,50000.0],["change",3606.2,50.0]],"change_id":15962721908,"instrument_name":"ETH-PERPETUAL","prev_change_id":15962721687,"timestamp":1737453511463,"type":"change"}}}
Channel: book.ETH-PERPETUAL.100ms, Data: {"jsonrpc":"2.0","method":"subscription","params":{"channel":"book.ETH-PERPETUAL.100ms","data":{"asks":[],"bids":[["new",3606.75,50000.0],["delete",3606.45,0.0],["new",3370.0,10.0],["delete",3369.0,0.0]],"change_id":15962722288,"instrument_name":"ETH-PERPETUAL","prev_change_id":15962721908,"timestamp":1737453512444,"type":"change"}}}
Channel: book.BNB_USDC.100ms, Data: {"jsonrpc":"2.0","method":"subscription","params":{"channel":"book.ETH-PERPETUAL.100ms","data":{"asks":[],"bids":[["delete",3606.75,0.0]],"change_id":15962722517,"instrument_name":"ETH-PERPETUAL","prev_change_id":15962722288,"timestamp":1737453512956,"type":"change"}}}
Channel: book.ETH-PERPETUAL.100ms, Data: {"jsonrpc":"2.0","method":"subscription","params":{"channel":"book.ETH-PERPETUAL.100ms","data":{"asks":[],"bids":[["new",3606.75,50000.0],["delete",3370.0,0.0],["new",3369.0,10.0]],"change_id":15962722591,"instrument_name":"ETH-PERPETUAL","prev_change_id":15962722517,"timestamp":1737453513121,"type":"change"}}}
Channel: book.BNB_USDC.100ms, Data: {"jsonrpc":"2.0","method":"subscription","params":{"channel":"book.ETH-PERPETUAL.100ms","data":{"asks":[],"bids":[["delete",3606.75,0.0],["new",3606.7,50000.0]],"change_id":15962722692,"instrument_name":"ETH-PERPETUAL","prev_change_id":15962722591,"timestamp":1737453513512,"type":"change"}}}
Channel: book.ETH-PERPETUAL.100ms, Data: {"jsonrpc":"2.0","method":"subscription","params":{"channel":"book.ETH-PERPETUAL.100ms","data":{"asks":[],"bids":[["delete",3606.7,0.0],["new",3606.45,50000.0],["new",3271.1,6091360.0],["delete",3270.85,0.0]],"change_id":15962722958,"instrument_name":"ETH-PERPETUAL","prev_change_id":15962722692,"timestamp":1737453514137,"type":"change"}}}
Channel: book.BNB_USDC.100ms, Data: {"jsonrpc":"2.0","method":"subscription","params":{"channel":"book.ETH-PERPETUAL.100ms","data":{"asks":[],"bids":[["delete",3606.45,0.0],["new",3606.05,50001.0]],"change_id":15962723068,"instrument_name":"ETH-PERPETUAL","prev_change_id":15962722958,"timestamp":1737453515236,"type":"change"}}}
Channel: book.ETH-PERPETUAL.100ms, Data: {"jsonrpc":"2.0","method":"subscription","params":{"channel":"book.ETH-PERPETUAL.100ms","data":{"asks":[],"bids":[["change",3606.05,1.0],["new",3605.9,50000.0]],"change_id":15962723460,"instrument_name":"ETH-PERPETUAL","prev_change_id":15962723068,"timestamp":1737453516181,"type":"change"}}}
Channel: book.BNB_USDC.100ms, Data: {"jsonrpc":"2.0","method":"subscription","params":{"channel":"book.ETH-PERPETUAL.100ms","data":{"asks":[],"bids":[["delete",3605.9,0.0],["new",3605.8,50000.0]],"change_id":15962723876,"instrument_name":"ETH-PERPETUAL","prev_change_id":15962723460,"timestamp":1737453517256,"type":"change"}}}
Channel: book.ETH-PERPETUAL.100ms, Data: {"jsonrpc":"2.0","method":"subscription","params":{"channel":"book.ETH-PERPETUAL.100ms","data":{"asks":[],"bids":[["delete",3605.8,0.0],["new",3605.3,50000.0]],"change_id":15962724351,"instrument_name":"ETH-PERPETUAL","prev_change_id":15962723876,"timestamp":1737453518322,"type":"change"}}}
Channel: book.ETH-PERPETUAL.100ms, Data: {"jsonrpc":"2.0","method":"subscription","params":{"channel":"book.ETH-PERPETUAL.100ms","data":{"asks":[],"bids":[["delete",3369.0,0.0],["new",3368.0,10.0]],"change_id":15962724487,"instrument_name":"ETH-PERPETUAL","prev_change_id":15962724351,"timestamp":1737453518764,"type":"change"}}}
Channel: book.ETH-PERPETUAL.100ms, Data: {"jsonrpc":"2.0","method":"subscription","params":{"channel":"book.ETH-PERPETUAL.100ms","data":{"asks":[],"bids":[["delete",3606.05,0.0]],"change_id":15962724567,"instrument_name":"ETH-PERPETUAL","prev_change_id":15962724487,"timestamp":1737453518946,"type":"change"}}}
Channel: book.BNB_USDC.100ms, Data: {"jsonrpc":"2.0","method":"subscription","params":{"channel":"book.ETH-PERPETUAL.100ms","data":{"asks":[],"bids":[["change",3605.35,50003.0],["delete",3605.3,0.0]],"change_id":15962724820,"instrument_name":"ETH-PERPETUAL","prev_change_id":15962724567,"timestamp":1737453519392,"type":"change"}}}
